Workbook

Sheet Newt Pricing and Sales Inputs
A1: Newt Pricing and Sales Inputs
A2: Newt Business Plan · Main Scenario
A4: Variable / dimension | B4: Newt Monthly Price | C4: Newt Included Checks | D4: Newt Overage Price | E4: Newt Checks per Repository | F4: Newt New Repositories | G4: Newt Monthly Churn
A5: Starter | B5: =49 -> 49 | C5: =100 -> 100 | D5: =0.3 -> 0.3 | E5: =100 -> 100 | F5: =3 -> 3 | G5: =0.03 -> 0.03
A6: Growth | B6: =149 -> 149 | C6: =500 -> 500 | D6: =0.25 -> 0.25 | E6: =400 -> 400 | F6: =1 -> 1 | G6: =0.03 -> 0.03
A7: Open source | B7: =0 -> 0 | C7: =30 -> 30 | D7: =0 -> 0 | E7: =30 -> 30 | F7: =5 -> 5 | G7: =0 -> 0

Sheet Newt Inputs
A1: Newt Inputs
A2: Newt Business Plan · Main Scenario
A4: Variable / dimension | B4: Value
A5: Newt Opening Cash | B5: =5000 -> 5000
A6: Newt Founder Draw | B6: =1500 -> 1500
A7: Newt Hosting | B7: =150 -> 150
A8: Newt Other Tools | B8: =100 -> 100
A9: Newt Payment Fee Rate | B9: =0.03 -> 0.03
A10: Newt Input Tokens per Check | B10: =10000 -> 10000
A11: Newt Output Tokens per Check | B11: =2000 -> 2000
A12: Newt Input Price per Million | B12: =3 -> 3
A13: Newt Output Price per Million | B13: =15 -> 15
A14: Newt Seconds per Check | B14: =30 -> 30
A15: Newt Computer Cost per Hour | B15: =0.12 -> 0.12
A16: Newt Retry and Log Allowance | B16: =0.039 -> 0.039
A17: Newt Cost per Check | B17: ='Newt Inputs'!B10*'Newt Inputs'!B12/1000000+'Newt Inputs'!B11*'Newt Inputs'!B13/1000000+'Newt Inputs'!B14*'Newt Inputs'!B15/3600+'Newt Inputs'!B16 -> 0.1

Sheet Newt Cost per Customer
A1: Newt Cost per Customer
A2: Newt Business Plan · Main Scenario
A4: Variable / dimension | B4: Newt Monthly Price | C4: Newt Checks per Repository | D4: Newt Direct Cost per Customer | E4: Newt Contribution per Customer | F4: Newt Contribution Margin | G4: Newt Cost at Full Quota
A5: Growth | B5: ='Newt Pricing and Sales Inputs'!B6 -> 149 | C5: ='Newt Pricing and Sales Inputs'!E6 -> 400 | D5: ='Newt Cost per Customer'!C5*'Newt Inputs'!B17+'Newt Cost per Customer'!B5*'Newt Inputs'!B9 -> 44.47 | E5: ='Newt Cost per Customer'!B5-'Newt Cost per Customer'!D5 -> 104.53 | F5: =IFERROR('Newt Cost per Customer'!E5/'Newt Cost per Customer'!B5,"") -> 0.70154362 | G5: ='Newt Pricing and Sales Inputs'!C6*'Newt Inputs'!B17+'Newt Cost per Customer'!B5*'Newt Inputs'!B9 -> 54.47
A6: Open source | B6: ='Newt Pricing and Sales Inputs'!B7 -> 0 | C6: ='Newt Pricing and Sales Inputs'!E7 -> 30 | D6: ='Newt Cost per Customer'!C6*'Newt Inputs'!B17+'Newt Cost per Customer'!B6*'Newt Inputs'!B9 -> 3 | E6: ='Newt Cost per Customer'!B6-'Newt Cost per Customer'!D6 -> -3 | F6: =IFERROR('Newt Cost per Customer'!E6/'Newt Cost per Customer'!B6,"") | G6: ='Newt Pricing and Sales Inputs'!C7*'Newt Inputs'!B17+'Newt Cost per Customer'!B6*'Newt Inputs'!B9 -> 3
A7: Starter | B7: ='Newt Pricing and Sales Inputs'!B5 -> 49 | C7: ='Newt Pricing and Sales Inputs'!E5 -> 100 | D7: ='Newt Cost per Customer'!C7*'Newt Inputs'!B17+'Newt Cost per Customer'!B7*'Newt Inputs'!B9 -> 11.47 | E7: ='Newt Cost per Customer'!B7-'Newt Cost per Customer'!D7 -> 37.53 | F7: =IFERROR('Newt Cost per Customer'!E7/'Newt Cost per Customer'!B7,"") -> 0.76591837 | G7: ='Newt Pricing and Sales Inputs'!C5*'Newt Inputs'!B17+'Newt Cost per Customer'!B7*'Newt Inputs'!B9 -> 11.47

Sheet Newt 12-Month Forecast
A1: Newt 12-Month Forecast
A2: Newt Business Plan · Main Scenario
A4: Variable / dimension | B4: 2026-10 | C4: 2026-11 | D4: 2026-12 | E4: 2027-01 | F4: 2027-02 | G4: 2027-03 | H4: 2027-04 | I4: 2027-05 | J4: 2027-06 | K4: 2027-07 | L4: 2027-08 | M4: 2027-09
A5: Newt Active Repositories | B5: =SUM('Newt 12-Month Forecast'!B6,'Newt 12-Month Forecast'!B7,'Newt 12-Month Forecast'!B8) -> 9 | C5: =SUM('Newt 12-Month Forecast'!C6,'Newt 12-Month Forecast'!C7,'Newt 12-Month Forecast'!C8) -> 17.88 | D5: =SUM('Newt 12-Month Forecast'!D6,'Newt 12-Month Forecast'!D7,'Newt 12-Month Forecast'!D8) -> 26.6436 | E5: =SUM('Newt 12-Month Forecast'!E6,'Newt 12-Month Forecast'!E7,'Newt 12-Month Forecast'!E8) -> 35.294292 | F5: =SUM('Newt 12-Month Forecast'!F6,'Newt 12-Month Forecast'!F7,'Newt 12-Month Forecast'!F8) -> 43.835463 | G5: =SUM('Newt 12-Month Forecast'!G6,'Newt 12-Month Forecast'!G7,'Newt 12-Month Forecast'!G8) -> 52.270399 | H5: =SUM('Newt 12-Month Forecast'!H6,'Newt 12-Month Forecast'!H7,'Newt 12-Month Forecast'!H8) -> 60.602287 | I5: =SUM('Newt 12-Month Forecast'!I6,'Newt 12-Month Forecast'!I7,'Newt 12-Month Forecast'!I8) -> 68.834219 | ... M5: =SUM('Newt 12-Month Forecast'!M6,'Newt 12-Month Forecast'!M7,'Newt 12-Month Forecast'!M8) -> 100.82102
A6: Growth | B6: ='Model inputs'!B7*(1-'Newt Pricing and Sales Inputs'!G6)+'Newt Pricing and Sales Inputs'!F6 -> 1 | C6: ='Newt 12-Month Forecast'!B6*(1-'Newt Pricing and Sales Inputs'!G6)+'Newt Pricing and Sales Inputs'!F6 -> 1.97 | D6: ='Newt 12-Month Forecast'!C6*(1-'Newt Pricing and Sales Inputs'!G6)+'Newt Pricing and Sales Inputs'!F6 -> 2.9109 | E6: ='Newt 12-Month Forecast'!D6*(1-'Newt Pricing and Sales Inputs'!G6)+'Newt Pricing and Sales Inputs'!F6 -> 3.823573 | F6: ='Newt 12-Month Forecast'!E6*(1-'Newt Pricing and Sales Inputs'!G6)+'Newt Pricing and Sales Inputs'!F6 -> 4.7088658 | G6: ='Newt 12-Month Forecast'!F6*(1-'Newt Pricing and Sales Inputs'!G6)+'Newt Pricing and Sales Inputs'!F6 -> 5.5675998 | H6: ='Newt 12-Month Forecast'!G6*(1-'Newt Pricing and Sales Inputs'!G6)+'Newt Pricing and Sales Inputs'!F6 -> 6.4005718 | I6: ='Newt 12-Month Forecast'!H6*(1-'Newt Pricing and Sales Inputs'!G6)+'Newt Pricing and Sales Inputs'!F6 -> 7.2085547 | J6: ='Newt 12-Month Forecast'!I6*(1-'Newt Pricing and Sales Inputs'!G6)+'Newt Pricing and Sales Inputs'!F6 -> 7.992298 | K6: ='Newt 12-Month Forecast'!J6*(1-'Newt Pricing and Sales Inputs'!G6)+'Newt Pricing and Sales Inputs'!F6 -> 8.7525291 | L6: ='Newt 12-Month Forecast'!K6*(1-'Newt Pricing and Sales Inputs'!G6)+'Newt Pricing and Sales Inputs'!F6 -> 9.4899532 | M6: ='Newt 12-Month Forecast'!L6*(1-'Newt Pricing and Sales Inputs'!G6)+'Newt Pricing and Sales Inputs'!F6 -> 10.205255
A7: Open source | B7: ='Model inputs'!B8*(1-'Newt Pricing and Sales Inputs'!G7)+'Newt Pricing and Sales Inputs'!F7 -> 5 | C7: ='Newt 12-Month Forecast'!B7*(1-'Newt Pricing and Sales Inputs'!G7)+'Newt Pricing and Sales Inputs'!F7 -> 10 | D7: ='Newt 12-Month Forecast'!C7*(1-'Newt Pricing and Sales Inputs'!G7)+'Newt Pricing and Sales Inputs'!F7 -> 15 | E7: ='Newt 12-Month Forecast'!D7*(1-'Newt Pricing and Sales Inputs'!G7)+'Newt Pricing and Sales Inputs'!F7 -> 20 | F7: ='Newt 12-Month Forecast'!E7*(1-'Newt Pricing and Sales Inputs'!G7)+'Newt Pricing and Sales Inputs'!F7 -> 25 | G7: ='Newt 12-Month Forecast'!F7*(1-'Newt Pricing and Sales Inputs'!G7)+'Newt Pricing and Sales Inputs'!F7 -> 30 | H7: ='Newt 12-Month Forecast'!G7*(1-'Newt Pricing and Sales Inputs'!G7)+'Newt Pricing and Sales Inputs'!F7 -> 35 | I7: ='Newt 12-Month Forecast'!H7*(1-'Newt Pricing and Sales Inputs'!G7)+'Newt Pricing and Sales Inputs'!F7 -> 40 | J7: ='Newt 12-Month Forecast'!I7*(1-'Newt Pricing and Sales Inputs'!G7)+'Newt Pricing and Sales Inputs'!F7 -> 45 | K7: ='Newt 12-Month Forecast'!J7*(1-'Newt Pricing and Sales Inputs'!G7)+'Newt Pricing and Sales Inputs'!F7 -> 50 | L7: ='Newt 12-Month Forecast'!K7*(1-'Newt Pricing and Sales Inputs'!G7)+'Newt Pricing and Sales Inputs'!F7 -> 55 | M7: ='Newt 12-Month Forecast'!L7*(1-'Newt Pricing and Sales Inputs'!G7)+'Newt Pricing and Sales Inputs'!F7 -> 60
A8: Starter | B8: ='Model inputs'!B9*(1-'Newt Pricing and Sales Inputs'!G5)+'Newt Pricing and Sales Inputs'!F5 -> 3 | C8: ='Newt 12-Month Forecast'!B8*(1-'Newt Pricing and Sales Inputs'!G5)+'Newt Pricing and Sales Inputs'!F5 -> 5.91 | D8: ='Newt 12-Month Forecast'!C8*(1-'Newt Pricing and Sales Inputs'!G5)+'Newt Pricing and Sales Inputs'!F5 -> 8.7327 | E8: ='Newt 12-Month Forecast'!D8*(1-'Newt Pricing and Sales Inputs'!G5)+'Newt Pricing and Sales Inputs'!F5 -> 11.470719 | F8: ='Newt 12-Month Forecast'!E8*(1-'Newt Pricing and Sales Inputs'!G5)+'Newt Pricing and Sales Inputs'!F5 -> 14.126597 | G8: ='Newt 12-Month Forecast'!F8*(1-'Newt Pricing and Sales Inputs'!G5)+'Newt Pricing and Sales Inputs'!F5 -> 16.7028 | H8: ='Newt 12-Month Forecast'!G8*(1-'Newt Pricing and Sales Inputs'!G5)+'Newt Pricing and Sales Inputs'!F5 -> 19.201716 | I8: ='Newt 12-Month Forecast'!H8*(1-'Newt Pricing and Sales Inputs'!G5)+'Newt Pricing and Sales Inputs'!F5 -> 21.625664 | J8: ='Newt 12-Month Forecast'!I8*(1-'Newt Pricing and Sales Inputs'!G5)+'Newt Pricing and Sales Inputs'!F5 -> 23.976894 | K8: ='Newt 12-Month Forecast'!J8*(1-'Newt Pricing and Sales Inputs'!G5)+'Newt Pricing and Sales Inputs'!F5 -> 26.257587 | L8: ='Newt 12-Month Forecast'!K8*(1-'Newt Pricing and Sales Inputs'!G5)+'Newt Pricing and Sales Inputs'!F5 -> 28.46986 | M8: ='Newt 12-Month Forecast'!L8*(1-'Newt Pricing and Sales Inputs'!G5)+'Newt Pricing and Sales Inputs'!F5 -> 30.615764
A9: Newt Revenue | B9: =SUM('Newt 12-Month Forecast'!B10,'Newt 12-Month Forecast'!B11,'Newt 12-Month Forecast'!B12) -> 296 | C9: =SUM('Newt 12-Month Forecast'!C10,'Newt 12-Month Forecast'!C11,'Newt 12-Month Forecast'!C12) -> 583.12 | D9: =SUM('Newt 12-Month Forecast'!D10,'Newt 12-Month Forecast'!D11,'Newt 12-Month Forecast'!D12) -> 861.6264 | E9: =SUM('Newt 12-Month Forecast'!E10,'Newt 12-Month Forecast'!E11,'Newt 12-Month Forecast'!E12) -> 1131.7776 | F9: =SUM('Newt 12-Month Forecast'!F10,'Newt 12-Month Forecast'!F11,'Newt 12-Month Forecast'!F12) -> 1393.8243 | G9: =SUM('Newt 12-Month Forecast'!G10,'Newt 12-Month Forecast'!G11,'Newt 12-Month Forecast'!G12) -> 1648.0096 | H9: =SUM('Newt 12-Month Forecast'!H10,'Newt 12-Month Forecast'!H11,'Newt 12-Month Forecast'!H12) -> 1894.5693 | I9: =SUM('Newt 12-Month Forecast'!I10,'Newt 12-Month Forecast'!I11,'Newt 12-Month Forecast'!I12) -> 2133.7322 | ... M9: =SUM('Newt 12-Month Forecast'!M10,'Newt 12-Month Forecast'!M11,'Newt 12-Month Forecast'!M12) -> 3020.7554
A10: Growth | B10: ='Newt 12-Month Forecast'!B6*('Newt Pricing and Sales Inputs'!B6+MAX(0,'Newt Pricing and Sales Inputs'!E6-'Newt Pricing and Sales Inputs'!C6)*'Newt Pricing and Sales Inputs'!D6) -> 149 | C10: ='Newt 12-Month Forecast'!C6*('Newt Pricing and Sales Inputs'!B6+MAX(0,'Newt Pricing and Sales Inputs'!E6-'Newt Pricing and Sales Inputs'!C6)*'Newt Pricing and Sales Inputs'!D6) -> 293.53 | D10: ='Newt 12-Month Forecast'!D6*('Newt Pricing and Sales Inputs'!B6+MAX(0,'Newt Pricing and Sales Inputs'!E6-'Newt Pricing and Sales Inputs'!C6)*'Newt Pricing and Sales Inputs'!D6) -> 433.7241 | E10: ='Newt 12-Month Forecast'!E6*('Newt Pricing and Sales Inputs'!B6+MAX(0,'Newt Pricing and Sales Inputs'!E6-'Newt Pricing and Sales Inputs'!C6)*'Newt Pricing and Sales Inputs'!D6) -> 569.71238 | F10: ='Newt 12-Month Forecast'!F6*('Newt Pricing and Sales Inputs'!B6+MAX(0,'Newt Pricing and Sales Inputs'!E6-'Newt Pricing and Sales Inputs'!C6)*'Newt Pricing and Sales Inputs'!D6) -> 701.62101 | G10: ='Newt 12-Month Forecast'!G6*('Newt Pricing and Sales Inputs'!B6+MAX(0,'Newt Pricing and Sales Inputs'!E6-'Newt Pricing and Sales Inputs'!C6)*'Newt Pricing and Sales Inputs'!D6) -> 829.57238 | H10: ='Newt 12-Month Forecast'!H6*('Newt Pricing and Sales Inputs'!B6+MAX(0,'Newt Pricing and Sales Inputs'!E6-'Newt Pricing and Sales Inputs'!C6)*'Newt Pricing and Sales Inputs'!D6) -> 953.6852 | I10: ='Newt 12-Month Forecast'!I6*('Newt Pricing and Sales Inputs'!B6+MAX(0,'Newt Pricing and Sales Inputs'!E6-'Newt Pricing and Sales Inputs'!C6)*'Newt Pricing and Sales Inputs'!D6) -> 1074.0746 | J10: ='Newt 12-Month Forecast'!J6*('Newt Pricing and Sales Inputs'!B6+MAX(0,'Newt Pricing and Sales Inputs'!E6-'Newt Pricing and Sales Inputs'!C6)*'Newt Pricing and Sales Inputs'!D6) -> 1190.8524 | K10: ='Newt 12-Month Forecast'!K6*('Newt Pricing and Sales Inputs'!B6+MAX(0,'Newt Pricing and Sales Inputs'!E6-'Newt Pricing and Sales Inputs'!C6)*'Newt Pricing and Sales Inputs'!D6) -> 1304.1268 | L10: ='Newt 12-Month Forecast'!L6*('Newt Pricing and Sales Inputs'!B6+MAX(0,'Newt Pricing and Sales Inputs'!E6-'Newt Pricing and Sales Inputs'!C6)*'Newt Pricing and Sales Inputs'!D6) -> 1414.003 | M10: ='Newt 12-Month Forecast'!M6*('Newt Pricing and Sales Inputs'!B6+MAX(0,'Newt Pricing and Sales Inputs'!E6-'Newt Pricing and Sales Inputs'!C6)*'Newt Pricing and Sales Inputs'!D6) -> 1520.5829
A11: Open source | B11: ='Newt 12-Month Forecast'!B7*('Newt Pricing and Sales Inputs'!B7+MAX(0,'Newt Pricing and Sales Inputs'!E7-'Newt Pricing and Sales Inputs'!C7)*'Newt Pricing and Sales Inputs'!D7) -> 0 | C11: ='Newt 12-Month Forecast'!C7*('Newt Pricing and Sales Inputs'!B7+MAX(0,'Newt Pricing and Sales Inputs'!E7-'Newt Pricing and Sales Inputs'!C7)*'Newt Pricing and Sales Inputs'!D7) -> 0 | D11: ='Newt 12-Month Forecast'!D7*('Newt Pricing and Sales Inputs'!B7+MAX(0,'Newt Pricing and Sales Inputs'!E7-'Newt Pricing and Sales Inputs'!C7)*'Newt Pricing and Sales Inputs'!D7) -> 0 | E11: ='Newt 12-Month Forecast'!E7*('Newt Pricing and Sales Inputs'!B7+MAX(0,'Newt Pricing and Sales Inputs'!E7-'Newt Pricing and Sales Inputs'!C7)*'Newt Pricing and Sales Inputs'!D7) -> 0 | F11: ='Newt 12-Month Forecast'!F7*('Newt Pricing and Sales Inputs'!B7+MAX(0,'Newt Pricing and Sales Inputs'!E7-'Newt Pricing and Sales Inputs'!C7)*'Newt Pricing and Sales Inputs'!D7) -> 0 | G11: ='Newt 12-Month Forecast'!G7*('Newt Pricing and Sales Inputs'!B7+MAX(0,'Newt Pricing and Sales Inputs'!E7-'Newt Pricing and Sales Inputs'!C7)*'Newt Pricing and Sales Inputs'!D7) -> 0 | H11: ='Newt 12-Month Forecast'!H7*('Newt Pricing and Sales Inputs'!B7+MAX(0,'Newt Pricing and Sales Inputs'!E7-'Newt Pricing and Sales Inputs'!C7)*'Newt Pricing and Sales Inputs'!D7) -> 0 | I11: ='Newt 12-Month Forecast'!I7*('Newt Pricing and Sales Inputs'!B7+MAX(0,'Newt Pricing and Sales Inputs'!E7-'Newt Pricing and Sales Inputs'!C7)*'Newt Pricing and Sales Inputs'!D7) -> 0 | J11: ='Newt 12-Month Forecast'!J7*('Newt Pricing and Sales Inputs'!B7+MAX(0,'Newt Pricing and Sales Inputs'!E7-'Newt Pricing and Sales Inputs'!C7)*'Newt Pricing and Sales Inputs'!D7) -> 0 | K11: ='Newt 12-Month Forecast'!K7*('Newt Pricing and Sales Inputs'!B7+MAX(0,'Newt Pricing and Sales Inputs'!E7-'Newt Pricing and Sales Inputs'!C7)*'Newt Pricing and Sales Inputs'!D7) -> 0 | L11: ='Newt 12-Month Forecast'!L7*('Newt Pricing and Sales Inputs'!B7+MAX(0,'Newt Pricing and Sales Inputs'!E7-'Newt Pricing and Sales Inputs'!C7)*'Newt Pricing and Sales Inputs'!D7) -> 0 | M11: ='Newt 12-Month Forecast'!M7*('Newt Pricing and Sales Inputs'!B7+MAX(0,'Newt Pricing and Sales Inputs'!E7-'Newt Pricing and Sales Inputs'!C7)*'Newt Pricing and Sales Inputs'!D7) -> 0
A12: Starter | B12: ='Newt 12-Month Forecast'!B8*('Newt Pricing and Sales Inputs'!B5+MAX(0,'Newt Pricing and Sales Inputs'!E5-'Newt Pricing and Sales Inputs'!C5)*'Newt Pricing and Sales Inputs'!D5) -> 147 | C12: ='Newt 12-Month Forecast'!C8*('Newt Pricing and Sales Inputs'!B5+MAX(0,'Newt Pricing and Sales Inputs'!E5-'Newt Pricing and Sales Inputs'!C5)*'Newt Pricing and Sales Inputs'!D5) -> 289.59 | D12: ='Newt 12-Month Forecast'!D8*('Newt Pricing and Sales Inputs'!B5+MAX(0,'Newt Pricing and Sales Inputs'!E5-'Newt Pricing and Sales Inputs'!C5)*'Newt Pricing and Sales Inputs'!D5) -> 427.9023 | E12: ='Newt 12-Month Forecast'!E8*('Newt Pricing and Sales Inputs'!B5+MAX(0,'Newt Pricing and Sales Inputs'!E5-'Newt Pricing and Sales Inputs'!C5)*'Newt Pricing and Sales Inputs'!D5) -> 562.06523 | F12: ='Newt 12-Month Forecast'!F8*('Newt Pricing and Sales Inputs'!B5+MAX(0,'Newt Pricing and Sales Inputs'!E5-'Newt Pricing and Sales Inputs'!C5)*'Newt Pricing and Sales Inputs'!D5) -> 692.20327 | G12: ='Newt 12-Month Forecast'!G8*('Newt Pricing and Sales Inputs'!B5+MAX(0,'Newt Pricing and Sales Inputs'!E5-'Newt Pricing and Sales Inputs'!C5)*'Newt Pricing and Sales Inputs'!D5) -> 818.43718 | H12: ='Newt 12-Month Forecast'!H8*('Newt Pricing and Sales Inputs'!B5+MAX(0,'Newt Pricing and Sales Inputs'!E5-'Newt Pricing and Sales Inputs'!C5)*'Newt Pricing and Sales Inputs'!D5) -> 940.88406 | I12: ='Newt 12-Month Forecast'!I8*('Newt Pricing and Sales Inputs'!B5+MAX(0,'Newt Pricing and Sales Inputs'!E5-'Newt Pricing and Sales Inputs'!C5)*'Newt Pricing and Sales Inputs'!D5) -> 1059.6575 | J12: ='Newt 12-Month Forecast'!J8*('Newt Pricing and Sales Inputs'!B5+MAX(0,'Newt Pricing and Sales Inputs'!E5-'Newt Pricing and Sales Inputs'!C5)*'Newt Pricing and Sales Inputs'!D5) -> 1174.8678 | K12: ='Newt 12-Month Forecast'!K8*('Newt Pricing and Sales Inputs'!B5+MAX(0,'Newt Pricing and Sales Inputs'!E5-'Newt Pricing and Sales Inputs'!C5)*'Newt Pricing and Sales Inputs'!D5) -> 1286.6218 | L12: ='Newt 12-Month Forecast'!L8*('Newt Pricing and Sales Inputs'!B5+MAX(0,'Newt Pricing and Sales Inputs'!E5-'Newt Pricing and Sales Inputs'!C5)*'Newt Pricing and Sales Inputs'!D5) -> 1395.0231 | M12: ='Newt 12-Month Forecast'!M8*('Newt Pricing and Sales Inputs'!B5+MAX(0,'Newt Pricing and Sales Inputs'!E5-'Newt Pricing and Sales Inputs'!C5)*'Newt Pricing and Sales Inputs'!D5) -> 1500.1724
A13: Newt Page Checks | B13: =SUM('Newt 12-Month Forecast'!B14,'Newt 12-Month Forecast'!B15,'Newt 12-Month Forecast'!B16) -> 850 | C13: =SUM('Newt 12-Month Forecast'!C14,'Newt 12-Month Forecast'!C15,'Newt 12-Month Forecast'!C16) -> 1679 | D13: =SUM('Newt 12-Month Forecast'!D14,'Newt 12-Month Forecast'!D15,'Newt 12-Month Forecast'!D16) -> 2487.63 | E13: =SUM('Newt 12-Month Forecast'!E14,'Newt 12-Month Forecast'!E15,'Newt 12-Month Forecast'!E16) -> 3276.5011 | F13: =SUM('Newt 12-Month Forecast'!F14,'Newt 12-Month Forecast'!F15,'Newt 12-Month Forecast'!F16) -> 4046.2061 | G13: =SUM('Newt 12-Month Forecast'!G14,'Newt 12-Month Forecast'!G15,'Newt 12-Month Forecast'!G16) -> 4797.3199 | H13: =SUM('Newt 12-Month Forecast'!H14,'Newt 12-Month Forecast'!H15,'Newt 12-Month Forecast'!H16) -> 5530.4003 | I13: =SUM('Newt 12-Month Forecast'!I14,'Newt 12-Month Forecast'!I15,'Newt 12-Month Forecast'!I16) -> 6245.9883 | ... M13: =SUM('Newt 12-Month Forecast'!M14,'Newt 12-Month Forecast'!M15,'Newt 12-Month Forecast'!M16) -> 8943.6782
A14: Growth | B14: ='Newt 12-Month Forecast'!B6*'Newt Pricing and Sales Inputs'!E6 -> 400 | C14: ='Newt 12-Month Forecast'!C6*'Newt Pricing and Sales Inputs'!E6 -> 788 | D14: ='Newt 12-Month Forecast'!D6*'Newt Pricing and Sales Inputs'!E6 -> 1164.36 | E14: ='Newt 12-Month Forecast'!E6*'Newt Pricing and Sales Inputs'!E6 -> 1529.4292 | F14: ='Newt 12-Month Forecast'!F6*'Newt Pricing and Sales Inputs'!E6 -> 1883.5463 | G14: ='Newt 12-Month Forecast'!G6*'Newt Pricing and Sales Inputs'!E6 -> 2227.0399 | H14: ='Newt 12-Month Forecast'!H6*'Newt Pricing and Sales Inputs'!E6 -> 2560.2287 | I14: ='Newt 12-Month Forecast'!I6*'Newt Pricing and Sales Inputs'!E6 -> 2883.4219 | J14: ='Newt 12-Month Forecast'!J6*'Newt Pricing and Sales Inputs'!E6 -> 3196.9192 | K14: ='Newt 12-Month Forecast'!K6*'Newt Pricing and Sales Inputs'!E6 -> 3501.0116 | L14: ='Newt 12-Month Forecast'!L6*'Newt Pricing and Sales Inputs'!E6 -> 3795.9813 | M14: ='Newt 12-Month Forecast'!M6*'Newt Pricing and Sales Inputs'!E6 -> 4082.1019
A15: Open source | B15: ='Newt 12-Month Forecast'!B7*'Newt Pricing and Sales Inputs'!E7 -> 150 | C15: ='Newt 12-Month Forecast'!C7*'Newt Pricing and Sales Inputs'!E7 -> 300 | D15: ='Newt 12-Month Forecast'!D7*'Newt Pricing and Sales Inputs'!E7 -> 450 | E15: ='Newt 12-Month Forecast'!E7*'Newt Pricing and Sales Inputs'!E7 -> 600 | F15: ='Newt 12-Month Forecast'!F7*'Newt Pricing and Sales Inputs'!E7 -> 750 | G15: ='Newt 12-Month Forecast'!G7*'Newt Pricing and Sales Inputs'!E7 -> 900 | H15: ='Newt 12-Month Forecast'!H7*'Newt Pricing and Sales Inputs'!E7 -> 1050 | I15: ='Newt 12-Month Forecast'!I7*'Newt Pricing and Sales Inputs'!E7 -> 1200 | J15: ='Newt 12-Month Forecast'!J7*'Newt Pricing and Sales Inputs'!E7 -> 1350 | K15: ='Newt 12-Month Forecast'!K7*'Newt Pricing and Sales Inputs'!E7 -> 1500 | L15: ='Newt 12-Month Forecast'!L7*'Newt Pricing and Sales Inputs'!E7 -> 1650 | M15: ='Newt 12-Month Forecast'!M7*'Newt Pricing and Sales Inputs'!E7 -> 1800
A16: Starter | B16: ='Newt 12-Month Forecast'!B8*'Newt Pricing and Sales Inputs'!E5 -> 300 | C16: ='Newt 12-Month Forecast'!C8*'Newt Pricing and Sales Inputs'!E5 -> 591 | D16: ='Newt 12-Month Forecast'!D8*'Newt Pricing and Sales Inputs'!E5 -> 873.27 | E16: ='Newt 12-Month Forecast'!E8*'Newt Pricing and Sales Inputs'!E5 -> 1147.0719 | F16: ='Newt 12-Month Forecast'!F8*'Newt Pricing and Sales Inputs'!E5 -> 1412.6597 | G16: ='Newt 12-Month Forecast'!G8*'Newt Pricing and Sales Inputs'!E5 -> 1670.28 | H16: ='Newt 12-Month Forecast'!H8*'Newt Pricing and Sales Inputs'!E5 -> 1920.1716 | I16: ='Newt 12-Month Forecast'!I8*'Newt Pricing and Sales Inputs'!E5 -> 2162.5664 | J16: ='Newt 12-Month Forecast'!J8*'Newt Pricing and Sales Inputs'!E5 -> 2397.6894 | K16: ='Newt 12-Month Forecast'!K8*'Newt Pricing and Sales Inputs'!E5 -> 2625.7587 | L16: ='Newt 12-Month Forecast'!L8*'Newt Pricing and Sales Inputs'!E5 -> 2846.986 | M16: ='Newt 12-Month Forecast'!M8*'Newt Pricing and Sales Inputs'!E5 -> 3061.5764
A17: Newt Paid Repositories | B17: ='Newt 12-Month Forecast'!B8+'Newt 12-Month Forecast'!B6 -> 4 | C17: ='Newt 12-Month Forecast'!C8+'Newt 12-Month Forecast'!C6 -> 7.88 | D17: ='Newt 12-Month Forecast'!D8+'Newt 12-Month Forecast'!D6 -> 11.6436 | E17: ='Newt 12-Month Forecast'!E8+'Newt 12-Month Forecast'!E6 -> 15.294292 | F17: ='Newt 12-Month Forecast'!F8+'Newt 12-Month Forecast'!F6 -> 18.835463 | G17: ='Newt 12-Month Forecast'!G8+'Newt 12-Month Forecast'!G6 -> 22.270399 | H17: ='Newt 12-Month Forecast'!H8+'Newt 12-Month Forecast'!H6 -> 25.602287 | I17: ='Newt 12-Month Forecast'!I8+'Newt 12-Month Forecast'!I6 -> 28.834219 | ... M17: ='Newt 12-Month Forecast'!M8+'Newt 12-Month Forecast'!M6 -> 40.821019
A18: Newt Testing Cost | B18: ='Newt 12-Month Forecast'!B13*'Newt Inputs'!B17 -> 85 | C18: ='Newt 12-Month Forecast'!C13*'Newt Inputs'!B17 -> 167.9 | D18: ='Newt 12-Month Forecast'!D13*'Newt Inputs'!B17 -> 248.763 | E18: ='Newt 12-Month Forecast'!E13*'Newt Inputs'!B17 -> 327.65011 | F18: ='Newt 12-Month Forecast'!F13*'Newt Inputs'!B17 -> 404.62061 | G18: ='Newt 12-Month Forecast'!G13*'Newt Inputs'!B17 -> 479.73199 | H18: ='Newt 12-Month Forecast'!H13*'Newt Inputs'!B17 -> 553.04003 | I18: ='Newt 12-Month Forecast'!I13*'Newt Inputs'!B17 -> 624.59883 | J18: ='Newt 12-Month Forecast'!J13*'Newt Inputs'!B17 -> 694.46086 | K18: ='Newt 12-Month Forecast'!K13*'Newt Inputs'!B17 -> 762.67704 | L18: ='Newt 12-Month Forecast'!L13*'Newt Inputs'!B17 -> 829.29673 | M18: ='Newt 12-Month Forecast'!M13*'Newt Inputs'!B17 -> 894.36782
A19: Newt Payment Fees | B19: ='Newt 12-Month Forecast'!B9*'Newt Inputs'!B9 -> 8.88 | C19: ='Newt 12-Month Forecast'!C9*'Newt Inputs'!B9 -> 17.4936 | D19: ='Newt 12-Month Forecast'!D9*'Newt Inputs'!B9 -> 25.848792 | E19: ='Newt 12-Month Forecast'!E9*'Newt Inputs'!B9 -> 33.953328 | F19: ='Newt 12-Month Forecast'!F9*'Newt Inputs'!B9 -> 41.814728 | G19: ='Newt 12-Month Forecast'!G9*'Newt Inputs'!B9 -> 49.440287 | H19: ='Newt 12-Month Forecast'!H9*'Newt Inputs'!B9 -> 56.837078 | I19: ='Newt 12-Month Forecast'!I9*'Newt Inputs'!B9 -> 64.011966 | J19: ='Newt 12-Month Forecast'!J9*'Newt Inputs'!B9 -> 70.971607 | K19: ='Newt 12-Month Forecast'!K9*'Newt Inputs'!B9 -> 77.722458 | L19: ='Newt 12-Month Forecast'!L9*'Newt Inputs'!B9 -> 84.270785 | M19: ='Newt 12-Month Forecast'!M9*'Newt Inputs'!B9 -> 90.622661
A20: Newt Business Cash Cost | B20: ='Newt 12-Month Forecast'!B18+'Newt 12-Month Forecast'!B19+'Newt Inputs'!B7+'Newt Inputs'!B8 -> 343.88 | C20: ='Newt 12-Month Forecast'!C18+'Newt 12-Month Forecast'!C19+'Newt Inputs'!B7+'Newt Inputs'!B8 -> 435.3936 | D20: ='Newt 12-Month Forecast'!D18+'Newt 12-Month Forecast'!D19+'Newt Inputs'!B7+'Newt Inputs'!B8 -> 524.61179 | E20: ='Newt 12-Month Forecast'!E18+'Newt 12-Month Forecast'!E19+'Newt Inputs'!B7+'Newt Inputs'!B8 -> 611.60344 | F20: ='Newt 12-Month Forecast'!F18+'Newt 12-Month Forecast'!F19+'Newt Inputs'!B7+'Newt Inputs'!B8 -> 696.43534 | G20: ='Newt 12-Month Forecast'!G18+'Newt 12-Month Forecast'!G19+'Newt Inputs'!B7+'Newt Inputs'!B8 -> 779.17228 | H20: ='Newt 12-Month Forecast'!H18+'Newt 12-Month Forecast'!H19+'Newt Inputs'!B7+'Newt Inputs'!B8 -> 859.87711 | I20: ='Newt 12-Month Forecast'!I18+'Newt 12-Month Forecast'!I19+'Newt Inputs'!B7+'Newt Inputs'!B8 -> 938.61079 | J20: ='Newt 12-Month Forecast'!J18+'Newt 12-Month Forecast'!J19+'Newt Inputs'!B7+'Newt Inputs'!B8 -> 1015.4325 | K20: ='Newt 12-Month Forecast'!K18+'Newt 12-Month Forecast'!K19+'Newt Inputs'!B7+'Newt Inputs'!B8 -> 1090.3995 | L20: ='Newt 12-Month Forecast'!L18+'Newt 12-Month Forecast'!L19+'Newt Inputs'!B7+'Newt Inputs'!B8 -> 1163.5675 | M20: ='Newt 12-Month Forecast'!M18+'Newt 12-Month Forecast'!M19+'Newt Inputs'!B7+'Newt Inputs'!B8 -> 1234.9905
A21: Newt Cash Before Founder Draw | B21: ='Newt 12-Month Forecast'!B9-'Newt 12-Month Forecast'!B20 -> -47.88 | C21: ='Newt 12-Month Forecast'!C9-'Newt 12-Month Forecast'!C20 -> 147.7264 | D21: ='Newt 12-Month Forecast'!D9-'Newt 12-Month Forecast'!D20 -> 337.01461 | E21: ='Newt 12-Month Forecast'!E9-'Newt 12-Month Forecast'!E20 -> 520.17417 | F21: ='Newt 12-Month Forecast'!F9-'Newt 12-Month Forecast'!F20 -> 697.38894 | G21: ='Newt 12-Month Forecast'!G9-'Newt 12-Month Forecast'!G20 -> 868.83728 | H21: ='Newt 12-Month Forecast'!H9-'Newt 12-Month Forecast'!H20 -> 1034.6922 | I21: ='Newt 12-Month Forecast'!I9-'Newt 12-Month Forecast'!I20 -> 1195.1214 | ... M21: ='Newt 12-Month Forecast'!M9-'Newt 12-Month Forecast'!M20 -> 1785.7649
A22: Newt Net Cash Flow | B22: ='Newt 12-Month Forecast'!B21-'Newt Inputs'!B6 -> -1547.88 | C22: ='Newt 12-Month Forecast'!C21-'Newt Inputs'!B6 -> -1352.2736 | D22: ='Newt 12-Month Forecast'!D21-'Newt Inputs'!B6 -> -1162.9854 | E22: ='Newt 12-Month Forecast'!E21-'Newt Inputs'!B6 -> -979.82583 | F22: ='Newt 12-Month Forecast'!F21-'Newt Inputs'!B6 -> -802.61106 | G22: ='Newt 12-Month Forecast'!G21-'Newt Inputs'!B6 -> -631.16272 | H22: ='Newt 12-Month Forecast'!H21-'Newt Inputs'!B6 -> -465.30784 | I22: ='Newt 12-Month Forecast'!I21-'Newt Inputs'!B6 -> -304.87861 | J22: ='Newt 12-Month Forecast'!J21-'Newt Inputs'!B6 -> -149.71225 | K22: ='Newt 12-Month Forecast'!K21-'Newt Inputs'!B6 -> 0.34911895 | L22: ='Newt 12-Month Forecast'!L21-'Newt Inputs'!B6 -> 145.45865 | M22: ='Newt 12-Month Forecast'!M21-'Newt Inputs'!B6 -> 285.76489
A23: Newt Cash Balance | B23: ='Model inputs'!B11+'Newt 12-Month Forecast'!B22 -> 3452.12 | C23: ='Newt 12-Month Forecast'!B23+'Newt 12-Month Forecast'!C22 -> 2099.8464 | D23: ='Newt 12-Month Forecast'!C23+'Newt 12-Month Forecast'!D22 -> 936.86101 | E23: ='Newt 12-Month Forecast'!D23+'Newt 12-Month Forecast'!E22 -> -42.964822 | F23: ='Newt 12-Month Forecast'!E23+'Newt 12-Month Forecast'!F22 -> -845.57588 | G23: ='Newt 12-Month Forecast'!F23+'Newt 12-Month Forecast'!G22 -> -1476.7386 | H23: ='Newt 12-Month Forecast'!G23+'Newt 12-Month Forecast'!H22 -> -1942.0464 | I23: ='Newt 12-Month Forecast'!H23+'Newt 12-Month Forecast'!I22 -> -2246.925 | J23: ='Newt 12-Month Forecast'!I23+'Newt 12-Month Forecast'!J22 -> -2396.6373 | ... M23: ='Newt 12-Month Forecast'!L23+'Newt 12-Month Forecast'!M22 -> -1965.0646

Sheet Model inputs
A1: Model inputs
A2: Integration values are aggregated snapshots; raw source records are not included.
A4: Variables
A5: Variable / segment | B5: 2026-09 | C5: 2026-10 | D5: 2026-11 | E5: 2026-12 | F5: 2027-01 | G5: 2027-02 | H5: 2027-03 | I5: 2027-04 | J5: 2027-05 | K5: 2027-06 | L5: 2027-07 | M5: 2027-08 | N5: 2027-09 | O5: Value | P5: Value
A6: Newt Active Repositories | B6: =SUM('Model inputs'!B7,'Model inputs'!B8,'Model inputs'!B9) -> 0 | C6: =SUM('Model inputs'!C7,'Model inputs'!C8,'Model inputs'!C9) -> 9 | D6: =SUM('Model inputs'!D7,'Model inputs'!D8,'Model inputs'!D9) -> 17.88 | E6: =SUM('Model inputs'!E7,'Model inputs'!E8,'Model inputs'!E9) -> 26.6436 | F6: =SUM('Model inputs'!F7,'Model inputs'!F8,'Model inputs'!F9) -> 35.294292 | G6: =SUM('Model inputs'!G7,'Model inputs'!G8,'Model inputs'!G9) -> 43.835463 | H6: =SUM('Model inputs'!H7,'Model inputs'!H8,'Model inputs'!H9) -> 52.270399 | I6: =SUM('Model inputs'!I7,'Model inputs'!I8,'Model inputs'!I9) -> 60.602287 | ... N6: =SUM('Model inputs'!N7,'Model inputs'!N8,'Model inputs'!N9) -> 100.82102
A7: Newt Active Repositories > Growth | B7: =0 -> 0 | C7: ='Model inputs'!B7*(1-'Model inputs'!P34)+'Model inputs'!P47 -> 1 | D7: ='Model inputs'!C7*(1-'Model inputs'!P34)+'Model inputs'!P47 -> 1.97 | E7: ='Model inputs'!D7*(1-'Model inputs'!P34)+'Model inputs'!P47 -> 2.9109 | F7: ='Model inputs'!E7*(1-'Model inputs'!P34)+'Model inputs'!P47 -> 3.823573 | G7: ='Model inputs'!F7*(1-'Model inputs'!P34)+'Model inputs'!P47 -> 4.7088658 | H7: ='Model inputs'!G7*(1-'Model inputs'!P34)+'Model inputs'!P47 -> 5.5675998 | I7: ='Model inputs'!H7*(1-'Model inputs'!P34)+'Model inputs'!P47 -> 6.4005718 | J7: ='Model inputs'!I7*(1-'Model inputs'!P34)+'Model inputs'!P47 -> 7.2085547 | K7: ='Model inputs'!J7*(1-'Model inputs'!P34)+'Model inputs'!P47 -> 7.992298 | L7: ='Model inputs'!K7*(1-'Model inputs'!P34)+'Model inputs'!P47 -> 8.7525291 | M7: ='Model inputs'!L7*(1-'Model inputs'!P34)+'Model inputs'!P47 -> 9.4899532 | N7: ='Model inputs'!M7*(1-'Model inputs'!P34)+'Model inputs'!P47 -> 10.205255
A8: Newt Active Repositories > Open source | B8: =0 -> 0 | C8: ='Model inputs'!B8*(1-'Model inputs'!P35)+'Model inputs'!P48 -> 5 | D8: ='Model inputs'!C8*(1-'Model inputs'!P35)+'Model inputs'!P48 -> 10 | E8: ='Model inputs'!D8*(1-'Model inputs'!P35)+'Model inputs'!P48 -> 15 | F8: ='Model inputs'!E8*(1-'Model inputs'!P35)+'Model inputs'!P48 -> 20 | G8: ='Model inputs'!F8*(1-'Model inputs'!P35)+'Model inputs'!P48 -> 25 | H8: ='Model inputs'!G8*(1-'Model inputs'!P35)+'Model inputs'!P48 -> 30 | I8: ='Model inputs'!H8*(1-'Model inputs'!P35)+'Model inputs'!P48 -> 35 | J8: ='Model inputs'!I8*(1-'Model inputs'!P35)+'Model inputs'!P48 -> 40 | K8: ='Model inputs'!J8*(1-'Model inputs'!P35)+'Model inputs'!P48 -> 45 | L8: ='Model inputs'!K8*(1-'Model inputs'!P35)+'Model inputs'!P48 -> 50 | M8: ='Model inputs'!L8*(1-'Model inputs'!P35)+'Model inputs'!P48 -> 55 | N8: ='Model inputs'!M8*(1-'Model inputs'!P35)+'Model inputs'!P48 -> 60
A9: Newt Active Repositories > Starter | B9: =0 -> 0 | C9: ='Model inputs'!B9*(1-'Model inputs'!P36)+'Model inputs'!P49 -> 3 | D9: ='Model inputs'!C9*(1-'Model inputs'!P36)+'Model inputs'!P49 -> 5.91 | E9: ='Model inputs'!D9*(1-'Model inputs'!P36)+'Model inputs'!P49 -> 8.7327 | F9: ='Model inputs'!E9*(1-'Model inputs'!P36)+'Model inputs'!P49 -> 11.470719 | G9: ='Model inputs'!F9*(1-'Model inputs'!P36)+'Model inputs'!P49 -> 14.126597 | H9: ='Model inputs'!G9*(1-'Model inputs'!P36)+'Model inputs'!P49 -> 16.7028 | I9: ='Model inputs'!H9*(1-'Model inputs'!P36)+'Model inputs'!P49 -> 19.201716 | J9: ='Model inputs'!I9*(1-'Model inputs'!P36)+'Model inputs'!P49 -> 21.625664 | K9: ='Model inputs'!J9*(1-'Model inputs'!P36)+'Model inputs'!P49 -> 23.976894 | L9: ='Model inputs'!K9*(1-'Model inputs'!P36)+'Model inputs'!P49 -> 26.257587 | M9: ='Model inputs'!L9*(1-'Model inputs'!P36)+'Model inputs'!P49 -> 28.46986 | N9: ='Model inputs'!M9*(1-'Model inputs'!P36)+'Model inputs'!P49 -> 30.615764
A10: Newt Business Cash Cost | B10: 0 | C10: ='Model inputs'!C66+'Model inputs'!C61+'Model inputs'!P24+'Model inputs'!P50 -> 343.88 | D10: ='Model inputs'!D66+'Model inputs'!D61+'Model inputs'!P24+'Model inputs'!P50 -> 435.3936 | E10: ='Model inputs'!E66+'Model inputs'!E61+'Model inputs'!P24+'Model inputs'!P50 -> 524.61179 | F10: ='Model inputs'!F66+'Model inputs'!F61+'Model inputs'!P24+'Model inputs'!P50 -> 611.60344 | G10: ='Model inputs'!G66+'Model inputs'!G61+'Model inputs'!P24+'Model inputs'!P50 -> 696.43534 | H10: ='Model inputs'!H66+'Model inputs'!H61+'Model inputs'!P24+'Model inputs'!P50 -> 779.17228 | I10: ='Model inputs'!I66+'Model inputs'!I61+'Model inputs'!P24+'Model inputs'!P50 -> 859.87711 | J10: ='Model inputs'!J66+'Model inputs'!J61+'Model inputs'!P24+'Model inputs'!P50 -> 938.61079 | K10: ='Model inputs'!K66+'Model inputs'!K61+'Model inputs'!P24+'Model inputs'!P50 -> 1015.4325 | L10: ='Model inputs'!L66+'Model inputs'!L61+'Model inputs'!P24+'Model inputs'!P50 -> 1090.3995 | M10: ='Model inputs'!M66+'Model inputs'!M61+'Model inputs'!P24+'Model inputs'!P50 -> 1163.5675 | N10: ='Model inputs'!N66+'Model inputs'!N61+'Model inputs'!P24+'Model inputs'!P50 -> 1234.9905
A11: Newt Cash Balance | B11: =IF('Model inputs'!P74="","",'Model inputs'!P74) -> 5000 | C11: ='Model inputs'!B11+'Model inputs'!C45 -> 3452.12 | D11: ='Model inputs'!C11+'Model inputs'!D45 -> 2099.8464 | E11: ='Model inputs'!D11+'Model inputs'!E45 -> 936.86101 | F11: ='Model inputs'!E11+'Model inputs'!F45 -> -42.964822 | G11: ='Model inputs'!F11+'Model inputs'!G45 -> -845.57588 | H11: ='Model inputs'!G11+'Model inputs'!H45 -> -1476.7386 | I11: ='Model inputs'!H11+'Model inputs'!I45 -> -1942.0464 | J11: ='Model inputs'!I11+'Model inputs'!J45 -> -2246.925 | ... N11: ='Model inputs'!M11+'Model inputs'!N45 -> -1965.0646
A12: Newt Cash Before Founder Draw | B12: 0 | C12: ='Model inputs'!C62-'Model inputs'!C10 -> -47.88 | D12: ='Model inputs'!D62-'Model inputs'!D10 -> 147.7264 | E12: ='Model inputs'!E62-'Model inputs'!E10 -> 337.01461 | F12: ='Model inputs'!F62-'Model inputs'!F10 -> 520.17417 | G12: ='Model inputs'!G62-'Model inputs'!G10 -> 697.38894 | H12: ='Model inputs'!H62-'Model inputs'!H10 -> 868.83728 | I12: ='Model inputs'!I62-'Model inputs'!I10 -> 1034.6922 | J12: ='Model inputs'!J62-'Model inputs'!J10 -> 1195.1214 | ... N12: ='Model inputs'!N62-'Model inputs'!N10 -> 1785.7649
A13: Newt Checks per Repository | O13: 0
A14: Newt Checks per Repository > Growth | O14: ='Newt Pricing and Sales Inputs'!E6 -> 400
A15: Newt Checks per Repository > Open source | O15: ='Newt Pricing and Sales Inputs'!E7 -> 30
A16: Newt Checks per Repository > Starter | O16: ='Newt Pricing and Sales Inputs'!E5 -> 100
A17: Newt Checks per Repository | P17: 0
A18: Newt Checks per Repository > Growth | P18: ='Newt Pricing and Sales Inputs'!E6 -> 400
A19: Newt Checks per Repository > Open source | P19: ='Newt Pricing and Sales Inputs'!E7 -> 30
A20: Newt Checks per Repository > Starter | P20: ='Newt Pricing and Sales Inputs'!E5 -> 100
A21: Newt Cost per Check · Newt Cost per Customer | O21: ='Model inputs'!O69*'Model inputs'!O68/1000000+'Model inputs'!O71*'Model inputs'!O70/1000000+'Model inputs'!O73*'Model inputs'!O67/3600+'Model inputs'!O72 -> 0.1
A22: Newt Cost per Check · Newt 12-Month Forecast | P22: ='Model inputs'!O69*'Model inputs'!O68/1000000+'Model inputs'!O71*'Model inputs'!O70/1000000+'Model inputs'!O73*'Model inputs'!O67/3600+'Model inputs'!O72 -> 0.1
A23: Newt Founder Draw | P23: ='Newt Inputs'!B6 -> 1500
A24: Newt Hosting | P24: ='Newt Inputs'!B7 -> 150
A25: Newt Included Checks | O25: 0
A26: Newt Included Checks > Growth | O26: ='Newt Pricing and Sales Inputs'!C6 -> 500
A27: Newt Included Checks > Open source | O27: ='Newt Pricing and Sales Inputs'!C7 -> 30
A28: Newt Included Checks > Starter | O28: ='Newt Pricing and Sales Inputs'!C5 -> 100
A29: Newt Included Checks | P29: 0
A30: Newt Included Checks > Growth | P30: ='Newt Pricing and Sales Inputs'!C6 -> 500
A31: Newt Included Checks > Open source | P31: ='Newt Pricing and Sales Inputs'!C7 -> 30
A32: Newt Included Checks > Starter | P32: ='Newt Pricing and Sales Inputs'!C5 -> 100
A33: Newt Monthly Churn | P33: 0
A34: Newt Monthly Churn > Growth | P34: ='Newt Pricing and Sales Inputs'!G6 -> 0.03
A35: Newt Monthly Churn > Open source | P35: ='Newt Pricing and Sales Inputs'!G7 -> 0
A36: Newt Monthly Churn > Starter | P36: ='Newt Pricing and Sales Inputs'!G5 -> 0.03
A37: Newt Monthly Price | O37: 0
A38: Newt Monthly Price > Growth | O38: ='Newt Pricing and Sales Inputs'!B6 -> 149
A39: Newt Monthly Price > Open source | O39: ='Newt Pricing and Sales Inputs'!B7 -> 0
A40: Newt Monthly Price > Starter | O40: ='Newt Pricing and Sales Inputs'!B5 -> 49
A41: Newt Monthly Price | P41: 0
...
